
# Created by Ruins mod version 13.8 Ingame Parser
# authoring Player: dexman545

weight=1
embed_into_distance=0
acceptable_target_blocks=
unacceptable_target_blocks=flowing_water,water,flowing_lava,lava
dimensions=13,13,12
allowable_overhang=0
max_leveling=2
leveling_buffer=0
preserve_water=0
preserve_lava=0

rule1=0,100,terrafirmacraft:WoodVert-4
rule2=0,100,terrafirmacraft:WoodConstruct-0
rule3=0,100,terrafirmacraft:StoneMMBrick-5
rule4=0,100,terrafirmacraft:StoneMMBrick-0
rule5=0,100,terrafirmacraft:DoorHickory-0
rule6=0,100,terrafirmacraft:Vessel-1
rule7=0,100,CarpentersBlocks:blockCarpentersLadder-3
rule8=0,100,terrafirmacraft:StoneSedBrick-7
rule9=0,100,terrafirmacraft:stoneSlabs-1
rule10=0,100,terrafirmacraft:StoneSedBrick-0
rule11=0,100,terrafirmacraft:Firepit-0
rule12=0,100,terrafirmacraft:stoneSlabs-4
rule13=0,100,terrafirmacraft:Chest TFC-3
rule14=0,100,terrafirmacraft:StoneIgExSmooth-2
rule15=0,100,minecraft:bed-0
rule16=0,100,minecraft:bed-8
rule17=0,100,terrafirmacraft:DoorHickory-8
rule18=0,100,terrafirmacraft:DoorHickory-9
rule19=0,100,minecraft:glass_pane-0
rule20=0,100,terrafirmacraft:Torch-10
rule21=0,100,minecraft:web-0
rule22=0,100,terrafirmacraft:Torch-9
rule23=0,100,terrafirmacraft:Torch-11
rule24=0,100,terrafirmacraft:Torch-4
rule25=0,100,terrafirmacraft:ToolRack-0
rule26=0,100,terrafirmacraft:Torch-3
rule27=0,100,terrafirmacraft:WoodHoriz-4
rule28=0,100,terrafirmacraft:WoodHoriz-12
rule29=0,100,terrafirmacraft:planks-9
rule30=0,100,CarpentersBlocks:blockCarpentersSlope-0
rule31=0,100,terrafirmacraft:MetalTrapDoor-4
rule32=0,100,terrafirmacraft:Thatch-0

layer
1,0,0,0,0,2,2,0,0,0,0,1
0,4,4,3,3,5,5,4,3,3,3,0
0,4,0,0,0,0,0,0,7,6,4,0
0,3,0,0,0,0,0,0,0,0,8,0
0,4,6,9,0,0,0,0,0,0,3,0
10,10,10,9,9,0,0,0,0,0,3,0
10,11,0,0,9,0,0,0,0,0,3,0
10,10,10,12,0,1,0,0,0,0,4,0
0,3,0,0,0,0,0,0,0,13,4,0
0,3,0,0,0,0,0,0,0,13,3,0
0,3,16,15,0,0,14,14,14,14,3,0
0,3,3,4,4,4,3,3,8,3,4,0
1,0,0,0,0,0,0,0,0,0,0,1
endlayer

layer
1,0,0,0,0,2,2,0,0,0,0,1
0,8,3,3,8,18,17,3,8,3,8,0
0,3,0,0,0,0,0,0,7,0,3,0
0,19,0,0,0,0,0,0,0,0,0,0
0,3,0,0,0,0,0,0,0,0,8,0
10,10,10,0,0,0,0,0,0,0,3,0
10,0,0,0,0,0,0,0,0,0,8,0
10,10,10,0,0,1,0,0,0,0,8,0
0,3,0,0,0,0,0,0,0,0,8,0
0,8,0,0,0,0,0,0,0,0,8,0
0,8,0,0,0,0,0,0,6,6,8,0
0,8,3,8,19,8,19,8,8,8,8,0
1,0,0,0,0,0,0,0,0,0,0,1
endlayer

layer
1,0,0,20,0,0,0,0,20,0,0,1
0,3,3,3,3,3,3,3,3,3,3,0
0,3,0,0,22,0,0,22,7,21,3,0
0,0,0,0,0,0,0,0,0,0,19,0
0,3,24,0,0,0,0,0,0,23,3,0
10,10,10,25,0,0,0,0,0,0,3,0
10,0,10,25,0,0,0,0,0,0,3,0
10,10,10,25,0,1,0,0,0,0,3,0
0,8,0,0,0,0,0,0,0,26,3,0
0,3,0,0,0,0,0,0,0,0,3,0
0,3,0,20,0,21,0,0,20,0,3,0
0,3,3,3,0,8,19,3,3,3,3,0
1,0,0,0,0,0,0,0,0,0,0,1
endlayer

layer
1,0,0,0,0,0,0,0,0,0,0,1
0,8,8,8,8,0,19,8,8,8,8,0
0,8,21,0,0,0,0,0,7,21,8,0
0,8,0,0,0,0,0,0,0,21,8,0
0,8,0,0,0,0,0,0,0,0,8,0
10,10,0,0,0,0,0,0,0,0,8,0
10,10,0,0,0,0,0,0,0,0,8,0
10,10,0,0,0,1,27,27,27,27,8,0
0,3,0,0,0,28,0,0,0,21,8,0
0,8,0,0,0,28,0,0,0,0,8,0
0,8,0,0,21,28,21,0,0,0,8,0
0,8,8,8,8,8,8,8,8,8,8,0
1,0,0,0,0,0,0,0,0,0,0,1
endlayer

layer
1,27,27,27,27,27,27,27,27,27,27,1
28,29,29,29,29,29,29,29,29,29,29,28
28,29,29,29,29,29,29,29,7,29,29,28
28,29,29,29,29,29,29,29,29,29,29,28
28,29,29,0,0,29,29,29,29,29,29,28
28,10,29,0,0,29,29,29,29,29,29,28
28,10,29,0,29,29,29,29,29,29,29,28
28,10,29,29,29,29,29,29,29,29,29,28
28,29,29,29,29,29,29,29,29,29,29,28
28,29,29,29,29,29,29,29,29,29,29,28
28,29,29,29,29,29,29,29,29,29,29,28
28,29,29,29,29,29,29,29,29,29,29,28
1,27,27,27,27,27,27,27,27,27,27,1
endlayer

layer
0,0,0,0,0,0,0,0,0,0,0,0
30,8,8,3,8,8,8,8,3,8,8,0
30,32,32,32,30,0,0,0,31,0,0,0
30,30,30,30,30,0,0,0,0,0,0,0
30,0,0,0,0,0,0,0,0,0,0,0
0,10,0,0,0,0,0,0,0,0,0,0
0,10,21,0,0,0,0,0,0,0,0,0
30,10,21,0,0,0,0,0,0,0,0,0
30,0,0,0,0,0,0,0,0,0,0,0
30,0,0,0,0,0,0,0,0,0,0,0
30,0,0,0,0,0,30,30,30,0,0,0
30,8,8,3,3,8,8,8,3,8,8,0
0,0,0,0,0,0,0,0,0,0,0,0
endlayer

layer
0,0,0,0,0,0,0,0,0,0,0,0
0,0,8,8,3,19,19,8,3,8,0,0
0,0,30,30,0,0,0,0,0,0,0,0
0,0,0,0,0,0,0,0,0,0,0,0
0,0,0,0,0,0,0,0,0,0,0,0
0,10,0,0,0,0,0,0,0,0,0,0
0,10,0,0,0,0,0,0,0,0,0,0
0,10,0,0,0,0,0,0,0,0,0,0
0,0,0,0,0,0,0,0,0,0,0,0
0,0,0,0,0,0,0,0,0,0,0,0
0,0,0,0,0,0,0,0,0,0,0,0
0,30,8,3,8,0,19,3,8,8,0,0
0,0,0,0,0,0,0,0,0,0,0,0
endlayer

layer
0,0,0,0,0,0,0,0,0,0,0,0
0,0,0,8,8,0,19,8,8,0,0,0
0,0,0,0,0,0,0,0,0,0,0,0
0,0,0,0,0,0,0,0,0,0,0,0
0,0,0,0,0,0,0,0,0,0,0,0
0,10,0,0,0,0,0,0,0,0,0,0
0,10,0,0,0,0,0,0,0,0,0,0
0,10,0,0,0,0,0,0,0,0,0,0
0,0,0,0,0,0,0,0,0,0,0,0
0,0,0,0,0,0,0,0,0,0,0,0
0,0,0,0,0,0,0,0,0,0,0,0
0,0,0,8,3,19,0,8,8,0,0,0
0,0,0,0,0,0,0,0,0,0,0,0
endlayer

layer
0,0,0,0,0,0,0,0,0,0,0,0
0,0,0,0,8,3,8,8,0,0,0,0
0,0,0,0,0,0,0,0,0,0,0,0
0,0,0,0,0,0,0,0,0,0,0,0
0,0,0,0,0,0,0,0,0,0,0,0
0,10,0,0,0,0,0,0,0,0,0,0
0,10,0,0,0,0,0,0,0,0,0,0
0,10,0,0,0,0,0,0,0,0,0,0
0,0,0,0,0,0,0,0,0,0,0,0
0,0,0,0,0,0,0,0,0,0,0,0
0,0,0,0,0,0,0,0,0,0,0,0
0,0,0,30,8,8,3,8,0,0,0,0
0,0,0,0,0,0,0,0,0,0,0,0
endlayer

layer
0,0,0,0,0,0,0,0,0,0,0,0
0,0,0,0,0,8,8,0,0,0,0,0
0,0,0,0,0,0,0,0,0,0,0,0
0,0,0,0,0,0,0,0,0,0,0,0
0,0,0,0,0,0,0,0,0,0,0,0
0,30,0,0,0,0,0,0,0,0,0,0
0,10,0,0,0,0,0,0,0,0,0,0
0,30,0,0,0,0,0,0,0,0,0,0
0,0,0,0,0,0,0,0,0,0,0,0
0,0,0,0,0,0,0,0,0,0,0,0
0,0,0,0,0,0,0,0,0,0,0,0
0,0,0,0,0,8,8,0,0,0,0,0
0,0,0,0,0,0,0,0,0,0,0,0
endlayer

layer
0,0,0,0,0,0,0,0,0,0,0,0
0,0,0,0,0,0,0,0,0,0,0,0
0,0,0,0,0,0,0,0,0,0,0,0
0,0,0,0,0,0,0,0,0,0,0,0
0,0,0,0,0,0,0,0,0,0,0,0
0,0,0,0,0,0,0,0,0,0,0,0
0,10,0,0,0,0,0,0,0,0,0,0
0,0,0,0,0,0,0,0,0,0,0,0
0,0,0,0,0,0,0,0,0,0,0,0
0,0,0,0,0,0,0,0,0,0,0,0
0,0,0,0,0,0,0,0,0,0,0,0
0,0,0,0,0,0,0,0,0,0,0,0
0,0,0,0,0,0,0,0,0,0,0,0
endlayer

layer
0,0,0,0,0,0,0,0,0,0,0,0
0,0,0,0,0,0,0,0,0,0,0,0
0,0,0,0,0,0,0,0,0,0,0,0
0,0,0,0,0,0,0,0,0,0,0,0
0,0,0,0,0,0,0,0,0,0,0,0
0,0,0,0,0,0,0,0,0,0,0,0
0,10,0,0,0,0,0,0,0,0,0,0
0,0,0,0,0,0,0,0,0,0,0,0
0,0,0,0,0,0,0,0,0,0,0,0
0,0,0,0,0,0,0,0,0,0,0,0
0,0,0,0,0,0,0,0,0,0,0,0
0,0,0,0,0,0,0,0,0,0,0,0
0,0,0,0,0,0,0,0,0,0,0,0
endlayer

layer
0,0,0,0,0,0,0,0,0,0,0,0
0,0,0,0,0,0,0,0,0,0,0,0
0,0,0,0,0,0,0,0,0,0,0,0
0,0,0,0,0,0,0,0,0,0,0,0
0,0,0,0,0,0,0,0,0,0,0,0
0,0,0,0,0,0,0,0,0,0,0,0
0,30,0,0,0,0,0,0,0,0,0,0
0,0,0,0,0,0,0,0,0,0,0,0
0,0,0,0,0,0,0,0,0,0,0,0
0,0,0,0,0,0,0,0,0,0,0,0
0,0,0,0,0,0,0,0,0,0,0,0
0,0,0,0,0,0,0,0,0,0,0,0
0,0,0,0,0,0,0,0,0,0,0,0
endlayer

